[2023-05-26T07:19:52.069+0000] {logging_mixin.py:149} INFO - Changing /opt/***/logs/dag_id=data_ingestion_gcs_dag/run_id=manual__2023-05-26T07:19:36.288103+00:00/task_id=from_local_to_gcs_task_2016 permission to 509
[2023-05-26T07:19:52.145+0000] {logging_mixin.py:149} INFO - Changing /opt/***/logs/dag_id=data_ingestion_gcs_dag/run_id=manual__2023-05-26T07:19:36.288103+00:00/task_id=from_local_to_gcs_task_2016 permission to 509
[2023-05-26T07:19:52.211+0000] {taskinstance.py:1103} INFO - Dependencies all met for dep_context=non-requeueable deps ti=<TaskInstance: data_ingestion_gcs_dag.from_local_to_gcs_task_2016 manual__2023-05-26T07:19:36.288103+00:00 [queued]>
[2023-05-26T07:19:52.241+0000] {taskinstance.py:1103} INFO - Dependencies all met for dep_context=requeueable deps ti=<TaskInstance: data_ingestion_gcs_dag.from_local_to_gcs_task_2016 manual__2023-05-26T07:19:36.288103+00:00 [queued]>
[2023-05-26T07:19:52.243+0000] {taskinstance.py:1308} INFO - Starting attempt 1 of 2
[2023-05-26T07:19:52.277+0000] {taskinstance.py:1327} INFO - Executing <Task(PythonOperator): from_local_to_gcs_task_2016> on 2023-05-26 07:19:36.288103+00:00
[2023-05-26T07:19:52.290+0000] {standard_task_runner.py:57} INFO - Started process 240 to run task
[2023-05-26T07:19:52.300+0000] {standard_task_runner.py:84} INFO - Running: ['***', 'tasks', 'run', 'data_ingestion_gcs_dag', 'from_local_to_gcs_task_2016', 'manual__2023-05-26T07:19:36.288103+00:00', '--job-id', '31', '--raw', '--subdir', 'DAGS_FOLDER/ingest_data_gcs_dag.py', '--cfg-path', '/tmp/tmpp3zk9u2c']
[2023-05-26T07:19:52.308+0000] {standard_task_runner.py:85} INFO - Job 31: Subtask from_local_to_gcs_task_2016
[2023-05-26T07:19:52.431+0000] {logging_mixin.py:149} INFO - Changing /opt/***/logs/dag_id=data_ingestion_gcs_dag/run_id=manual__2023-05-26T07:19:36.288103+00:00/task_id=from_local_to_gcs_task_2016 permission to 509
[2023-05-26T07:19:52.451+0000] {task_command.py:410} INFO - Running <TaskInstance: data_ingestion_gcs_dag.from_local_to_gcs_task_2016 manual__2023-05-26T07:19:36.288103+00:00 [running]> on host 71de5723b7f9
[2023-05-26T07:19:52.697+0000] {taskinstance.py:1547} INFO - Exporting env vars: AIRFLOW_CTX_DAG_OWNER='***' AIRFLOW_CTX_DAG_ID='data_ingestion_gcs_dag' AIRFLOW_CTX_TASK_ID='from_local_to_gcs_task_2016' AIRFLOW_CTX_EXECUTION_DATE='2023-05-26T07:19:36.288103+00:00' AIRFLOW_CTX_TRY_NUMBER='1' AIRFLOW_CTX_DAG_RUN_ID='manual__2023-05-26T07:19:36.288103+00:00'
[2023-05-26T07:19:52.807+0000] {taskinstance.py:1824} ERROR - Task failed with exception
Traceback (most recent call last):
  File "/home/airflow/.local/lib/python3.7/site-packages/airflow/operators/python.py", line 181, in execute
    return_value = self.execute_callable()
  File "/home/airflow/.local/lib/python3.7/site-packages/airflow/operators/python.py", line 198, in execute_callable
    return self.python_callable(*self.op_args, **self.op_kwargs)
  File "/opt/airflow/dags/ingest_data_gcs_dag.py", line 47, in upload_to_gcs
    blob.upload_from_filename(local_file)
  File "/home/airflow/.local/lib/python3.7/site-packages/google/cloud/storage/blob.py", line 2682, in upload_from_filename
    with open(filename, "rb") as file_obj:
FileNotFoundError: [Errno 2] No such file or directory: '/opt/airflow/Horticulture_2016.parquet'
[2023-05-26T07:19:52.844+0000] {taskinstance.py:1350} INFO - Marking task as UP_FOR_RETRY. dag_id=data_ingestion_gcs_dag, task_id=from_local_to_gcs_task_2016, execution_date=20230526T071936, start_date=20230526T071952, end_date=20230526T071952
[2023-05-26T07:19:52.902+0000] {standard_task_runner.py:109} ERROR - Failed to execute job 31 for task from_local_to_gcs_task_2016 ([Errno 2] No such file or directory: '/opt/airflow/Horticulture_2016.parquet'; 240)
[2023-05-26T07:19:52.956+0000] {local_task_job_runner.py:225} INFO - Task exited with return code 1
[2023-05-26T07:19:53.020+0000] {taskinstance.py:2651} INFO - 0 downstream tasks scheduled from follow-on schedule check
