[2023-05-26T11:10:22.744+0000] {logging_mixin.py:149} INFO - Changing /opt/***/logs/dag_id=ingest_data_gcs_dag/run_id=manual__2023-05-26T11:05:04.778661+00:00/task_id=bigquery_to_external_table_task_2016 permission to 509
[2023-05-26T11:10:22.775+0000] {logging_mixin.py:149} INFO - Changing /opt/***/logs/dag_id=ingest_data_gcs_dag/run_id=manual__2023-05-26T11:05:04.778661+00:00/task_id=bigquery_to_external_table_task_2016 permission to 509
[2023-05-26T11:10:22.805+0000] {taskinstance.py:1103} INFO - Dependencies all met for dep_context=non-requeueable deps ti=<TaskInstance: ingest_data_gcs_dag.bigquery_to_external_table_task_2016 manual__2023-05-26T11:05:04.778661+00:00 [queued]>
[2023-05-26T11:10:22.818+0000] {taskinstance.py:1103} INFO - Dependencies all met for dep_context=requeueable deps ti=<TaskInstance: ingest_data_gcs_dag.bigquery_to_external_table_task_2016 manual__2023-05-26T11:05:04.778661+00:00 [queued]>
[2023-05-26T11:10:22.819+0000] {taskinstance.py:1308} INFO - Starting attempt 2 of 2
[2023-05-26T11:10:22.838+0000] {taskinstance.py:1327} INFO - Executing <Task(BigQueryCreateExternalTableOperator): bigquery_to_external_table_task_2016> on 2023-05-26 11:05:04.778661+00:00
[2023-05-26T11:10:22.844+0000] {standard_task_runner.py:57} INFO - Started process 229 to run task
[2023-05-26T11:10:22.849+0000] {standard_task_runner.py:84} INFO - Running: ['***', 'tasks', 'run', 'ingest_data_gcs_dag', 'bigquery_to_external_table_task_2016', 'manual__2023-05-26T11:05:04.778661+00:00', '--job-id', '129', '--raw', '--subdir', 'DAGS_FOLDER/ingest_data_gcs_dag.py', '--cfg-path', '/tmp/tmp08t5ggd5']
[2023-05-26T11:10:22.853+0000] {standard_task_runner.py:85} INFO - Job 129: Subtask bigquery_to_external_table_task_2016
[2023-05-26T11:10:22.919+0000] {logging_mixin.py:149} INFO - Changing /opt/***/logs/dag_id=ingest_data_gcs_dag/run_id=manual__2023-05-26T11:05:04.778661+00:00/task_id=bigquery_to_external_table_task_2016 permission to 509
[2023-05-26T11:10:22.927+0000] {task_command.py:410} INFO - Running <TaskInstance: ingest_data_gcs_dag.bigquery_to_external_table_task_2016 manual__2023-05-26T11:05:04.778661+00:00 [running]> on host 335f5093005c
[2023-05-26T11:10:23.021+0000] {taskinstance.py:1547} INFO - Exporting env vars: AIRFLOW_CTX_DAG_OWNER='***' AIRFLOW_CTX_DAG_ID='ingest_data_gcs_dag' AIRFLOW_CTX_TASK_ID='bigquery_to_external_table_task_2016' AIRFLOW_CTX_EXECUTION_DATE='2023-05-26T11:05:04.778661+00:00' AIRFLOW_CTX_TRY_NUMBER='2' AIRFLOW_CTX_DAG_RUN_ID='manual__2023-05-26T11:05:04.778661+00:00'
[2023-05-26T11:10:23.024+0000] {crypto.py:83} WARNING - empty cryptography key - values will not be stored encrypted.
[2023-05-26T11:10:23.025+0000] {base.py:73} INFO - Using connection ID 'google_cloud_default' for task execution.
[2023-05-26T11:10:25.371+0000] {taskinstance.py:1824} ERROR - Task failed with exception
Traceback (most recent call last):
  File "/home/airflow/.local/lib/python3.7/site-packages/airflow/providers/google/cloud/operators/bigquery.py", line 1613, in execute
    table_resource=self.table_resource,
  File "/home/airflow/.local/lib/python3.7/site-packages/airflow/providers/google/common/hooks/base_google.py", line 468, in inner_wrapper
    return func(self, *args, **kwargs)
  File "/home/airflow/.local/lib/python3.7/site-packages/airflow/providers/google/cloud/hooks/bigquery.py", line 407, in create_empty_table
    table=table, exists_ok=exists_ok, retry=retry
  File "/home/airflow/.local/lib/python3.7/site-packages/google/cloud/bigquery/client.py", line 755, in create_table
    timeout=timeout,
  File "/home/airflow/.local/lib/python3.7/site-packages/google/cloud/bigquery/client.py", line 782, in _call_api
    return call()
  File "/home/airflow/.local/lib/python3.7/site-packages/google/api_core/retry.py", line 288, in retry_wrapped_func
    on_error=on_error,
  File "/home/airflow/.local/lib/python3.7/site-packages/google/api_core/retry.py", line 190, in retry_target
    return target()
  File "/home/airflow/.local/lib/python3.7/site-packages/google/cloud/_http/__init__.py", line 494, in api_request
    raise exceptions.from_http_response(response)
google.api_core.exceptions.Forbidden: 403 POST https://bigquery.googleapis.com/bigquery/v2/projects/bold-apricot-387206/datasets/horticulture_latest_dataset/tables?prettyPrint=false: Access Denied: Dataset bold-apricot-387206:horticulture_latest_dataset: Permission bigquery.tables.create denied on dataset bold-apricot-387206:horticulture_latest_dataset (or it may not exist).
[2023-05-26T11:10:25.385+0000] {taskinstance.py:1350} INFO - Marking task as FAILED. dag_id=ingest_data_gcs_dag, task_id=bigquery_to_external_table_task_2016, execution_date=20230526T110504, start_date=20230526T111022, end_date=20230526T111025
[2023-05-26T11:10:25.405+0000] {standard_task_runner.py:109} ERROR - Failed to execute job 129 for task bigquery_to_external_table_task_2016 (403 POST https://bigquery.googleapis.com/bigquery/v2/projects/bold-apricot-387206/datasets/horticulture_latest_dataset/tables?prettyPrint=false: Access Denied: Dataset bold-apricot-387206:horticulture_latest_dataset: Permission bigquery.tables.create denied on dataset bold-apricot-387206:horticulture_latest_dataset (or it may not exist).; 229)
[2023-05-26T11:10:25.451+0000] {local_task_job_runner.py:225} INFO - Task exited with return code 1
[2023-05-26T11:10:25.474+0000] {taskinstance.py:2651} INFO - 0 downstream tasks scheduled from follow-on schedule check
