[2023-05-27T12:52:17.622+0000] {logging_mixin.py:149} INFO - Changing /opt/***/logs/dag_id=ingest_data_gcs_dag/run_id=scheduled__2023-05-26T00:00:00+00:00/task_id=bigquery_to_external_table_task_2016 permission to 509
[2023-05-27T12:52:17.679+0000] {logging_mixin.py:149} INFO - Changing /opt/***/logs/dag_id=ingest_data_gcs_dag/run_id=scheduled__2023-05-26T00:00:00+00:00/task_id=bigquery_to_external_table_task_2016 permission to 509
[2023-05-27T12:52:17.722+0000] {taskinstance.py:1103} INFO - Dependencies all met for dep_context=non-requeueable deps ti=<TaskInstance: ingest_data_gcs_dag.bigquery_to_external_table_task_2016 scheduled__2023-05-26T00:00:00+00:00 [queued]>
[2023-05-27T12:52:17.752+0000] {taskinstance.py:1103} INFO - Dependencies all met for dep_context=requeueable deps ti=<TaskInstance: ingest_data_gcs_dag.bigquery_to_external_table_task_2016 scheduled__2023-05-26T00:00:00+00:00 [queued]>
[2023-05-27T12:52:17.753+0000] {taskinstance.py:1308} INFO - Starting attempt 1 of 2
[2023-05-27T12:52:17.786+0000] {taskinstance.py:1327} INFO - Executing <Task(BigQueryCreateExternalTableOperator): bigquery_to_external_table_task_2016> on 2023-05-26 00:00:00+00:00
[2023-05-27T12:52:17.794+0000] {standard_task_runner.py:57} INFO - Started process 12010 to run task
[2023-05-27T12:52:17.802+0000] {standard_task_runner.py:84} INFO - Running: ['***', 'tasks', 'run', 'ingest_data_gcs_dag', 'bigquery_to_external_table_task_2016', 'scheduled__2023-05-26T00:00:00+00:00', '--job-id', '157', '--raw', '--subdir', 'DAGS_FOLDER/ingest_data_gcs_dag.py', '--cfg-path', '/tmp/tmpgd6zh2gg']
[2023-05-27T12:52:17.807+0000] {standard_task_runner.py:85} INFO - Job 157: Subtask bigquery_to_external_table_task_2016
[2023-05-27T12:52:17.886+0000] {logging_mixin.py:149} INFO - Changing /opt/***/logs/dag_id=ingest_data_gcs_dag/run_id=scheduled__2023-05-26T00:00:00+00:00/task_id=bigquery_to_external_table_task_2016 permission to 509
[2023-05-27T12:52:17.896+0000] {task_command.py:410} INFO - Running <TaskInstance: ingest_data_gcs_dag.bigquery_to_external_table_task_2016 scheduled__2023-05-26T00:00:00+00:00 [running]> on host 335f5093005c
[2023-05-27T12:52:18.036+0000] {taskinstance.py:1547} INFO - Exporting env vars: AIRFLOW_CTX_DAG_OWNER='***' AIRFLOW_CTX_DAG_ID='ingest_data_gcs_dag' AIRFLOW_CTX_TASK_ID='bigquery_to_external_table_task_2016' AIRFLOW_CTX_EXECUTION_DATE='2023-05-26T00:00:00+00:00' AIRFLOW_CTX_TRY_NUMBER='1' AIRFLOW_CTX_DAG_RUN_ID='scheduled__2023-05-26T00:00:00+00:00'
[2023-05-27T12:52:18.042+0000] {crypto.py:83} WARNING - empty cryptography key - values will not be stored encrypted.
[2023-05-27T12:52:18.045+0000] {base.py:73} INFO - Using connection ID 'google_cloud_default' for task execution.
[2023-05-27T12:52:21.401+0000] {taskinstance.py:1824} ERROR - Task failed with exception
Traceback (most recent call last):
  File "/home/airflow/.local/lib/python3.7/site-packages/airflow/providers/google/cloud/operators/bigquery.py", line 1613, in execute
    table_resource=self.table_resource,
  File "/home/airflow/.local/lib/python3.7/site-packages/airflow/providers/google/common/hooks/base_google.py", line 468, in inner_wrapper
    return func(self, *args, **kwargs)
  File "/home/airflow/.local/lib/python3.7/site-packages/airflow/providers/google/cloud/hooks/bigquery.py", line 407, in create_empty_table
    table=table, exists_ok=exists_ok, retry=retry
  File "/home/airflow/.local/lib/python3.7/site-packages/google/cloud/bigquery/client.py", line 755, in create_table
    timeout=timeout,
  File "/home/airflow/.local/lib/python3.7/site-packages/google/cloud/bigquery/client.py", line 782, in _call_api
    return call()
  File "/home/airflow/.local/lib/python3.7/site-packages/google/api_core/retry.py", line 288, in retry_wrapped_func
    on_error=on_error,
  File "/home/airflow/.local/lib/python3.7/site-packages/google/api_core/retry.py", line 190, in retry_target
    return target()
  File "/home/airflow/.local/lib/python3.7/site-packages/google/cloud/_http/__init__.py", line 494, in api_request
    raise exceptions.from_http_response(response)
google.api_core.exceptions.Forbidden: 403 POST https://bigquery.googleapis.com/bigquery/v2/projects/bold-apricot-387206/datasets/horticulture_latest_dataset/tables?prettyPrint=false: Access Denied: Dataset bold-apricot-387206:horticulture_latest_dataset: Permission bigquery.tables.create denied on dataset bold-apricot-387206:horticulture_latest_dataset (or it may not exist).
[2023-05-27T12:52:21.421+0000] {taskinstance.py:1350} INFO - Marking task as UP_FOR_RETRY. dag_id=ingest_data_gcs_dag, task_id=bigquery_to_external_table_task_2016, execution_date=20230526T000000, start_date=20230527T125217, end_date=20230527T125221
[2023-05-27T12:52:21.459+0000] {standard_task_runner.py:109} ERROR - Failed to execute job 157 for task bigquery_to_external_table_task_2016 (403 POST https://bigquery.googleapis.com/bigquery/v2/projects/bold-apricot-387206/datasets/horticulture_latest_dataset/tables?prettyPrint=false: Access Denied: Dataset bold-apricot-387206:horticulture_latest_dataset: Permission bigquery.tables.create denied on dataset bold-apricot-387206:horticulture_latest_dataset (or it may not exist).; 12010)
[2023-05-27T12:52:21.479+0000] {local_task_job_runner.py:225} INFO - Task exited with return code 1
[2023-05-27T12:52:21.515+0000] {taskinstance.py:2651} INFO - 0 downstream tasks scheduled from follow-on schedule check
