[2023-05-26T07:19:51.992+0000] {logging_mixin.py:149} INFO - Changing /opt/***/logs/dag_id=data_ingestion_gcs_dag/run_id=manual__2023-05-26T07:19:36.288103+00:00/task_id=from_local_to_gcs_task_2015 permission to 509
[2023-05-26T07:19:52.073+0000] {logging_mixin.py:149} INFO - Changing /opt/***/logs/dag_id=data_ingestion_gcs_dag/run_id=manual__2023-05-26T07:19:36.288103+00:00/task_id=from_local_to_gcs_task_2015 permission to 509
[2023-05-26T07:19:52.139+0000] {taskinstance.py:1103} INFO - Dependencies all met for dep_context=non-requeueable deps ti=<TaskInstance: data_ingestion_gcs_dag.from_local_to_gcs_task_2015 manual__2023-05-26T07:19:36.288103+00:00 [queued]>
[2023-05-26T07:19:52.170+0000] {taskinstance.py:1103} INFO - Dependencies all met for dep_context=requeueable deps ti=<TaskInstance: data_ingestion_gcs_dag.from_local_to_gcs_task_2015 manual__2023-05-26T07:19:36.288103+00:00 [queued]>
[2023-05-26T07:19:52.171+0000] {taskinstance.py:1308} INFO - Starting attempt 1 of 2
[2023-05-26T07:19:52.209+0000] {taskinstance.py:1327} INFO - Executing <Task(PythonOperator): from_local_to_gcs_task_2015> on 2023-05-26 07:19:36.288103+00:00
[2023-05-26T07:19:52.223+0000] {standard_task_runner.py:57} INFO - Started process 239 to run task
[2023-05-26T07:19:52.241+0000] {standard_task_runner.py:84} INFO - Running: ['***', 'tasks', 'run', 'data_ingestion_gcs_dag', 'from_local_to_gcs_task_2015', 'manual__2023-05-26T07:19:36.288103+00:00', '--job-id', '30', '--raw', '--subdir', 'DAGS_FOLDER/ingest_data_gcs_dag.py', '--cfg-path', '/tmp/tmpmrec937t']
[2023-05-26T07:19:52.248+0000] {standard_task_runner.py:85} INFO - Job 30: Subtask from_local_to_gcs_task_2015
[2023-05-26T07:19:52.354+0000] {logging_mixin.py:149} INFO - Changing /opt/***/logs/dag_id=data_ingestion_gcs_dag/run_id=manual__2023-05-26T07:19:36.288103+00:00/task_id=from_local_to_gcs_task_2015 permission to 509
[2023-05-26T07:19:52.370+0000] {task_command.py:410} INFO - Running <TaskInstance: data_ingestion_gcs_dag.from_local_to_gcs_task_2015 manual__2023-05-26T07:19:36.288103+00:00 [running]> on host 71de5723b7f9
[2023-05-26T07:19:52.632+0000] {taskinstance.py:1547} INFO - Exporting env vars: AIRFLOW_CTX_DAG_OWNER='***' AIRFLOW_CTX_DAG_ID='data_ingestion_gcs_dag' AIRFLOW_CTX_TASK_ID='from_local_to_gcs_task_2015' AIRFLOW_CTX_EXECUTION_DATE='2023-05-26T07:19:36.288103+00:00' AIRFLOW_CTX_TRY_NUMBER='1' AIRFLOW_CTX_DAG_RUN_ID='manual__2023-05-26T07:19:36.288103+00:00'
[2023-05-26T07:19:52.786+0000] {taskinstance.py:1824} ERROR - Task failed with exception
Traceback (most recent call last):
  File "/home/airflow/.local/lib/python3.7/site-packages/airflow/operators/python.py", line 181, in execute
    return_value = self.execute_callable()
  File "/home/airflow/.local/lib/python3.7/site-packages/airflow/operators/python.py", line 198, in execute_callable
    return self.python_callable(*self.op_args, **self.op_kwargs)
  File "/opt/airflow/dags/ingest_data_gcs_dag.py", line 47, in upload_to_gcs
    blob.upload_from_filename(local_file)
  File "/home/airflow/.local/lib/python3.7/site-packages/google/cloud/storage/blob.py", line 2682, in upload_from_filename
    with open(filename, "rb") as file_obj:
FileNotFoundError: [Errno 2] No such file or directory: '/opt/airflow/Horticulture_2015.parquet'
[2023-05-26T07:19:52.821+0000] {taskinstance.py:1350} INFO - Marking task as UP_FOR_RETRY. dag_id=data_ingestion_gcs_dag, task_id=from_local_to_gcs_task_2015, execution_date=20230526T071936, start_date=20230526T071952, end_date=20230526T071952
[2023-05-26T07:19:52.864+0000] {standard_task_runner.py:109} ERROR - Failed to execute job 30 for task from_local_to_gcs_task_2015 ([Errno 2] No such file or directory: '/opt/airflow/Horticulture_2015.parquet'; 239)
[2023-05-26T07:19:52.900+0000] {local_task_job_runner.py:225} INFO - Task exited with return code 1
[2023-05-26T07:19:52.958+0000] {taskinstance.py:2651} INFO - 0 downstream tasks scheduled from follow-on schedule check
