[2023-05-26T08:27:41.167+0000] {logging_mixin.py:149} INFO - Changing /opt/***/logs/dag_id=ingest_data_gcs_dag/run_id=scheduled__2023-05-25T00:00:00+00:00/task_id=bigquery_to_external_table_task_2015 permission to 509
[2023-05-26T08:27:41.222+0000] {logging_mixin.py:149} INFO - Changing /opt/***/logs/dag_id=ingest_data_gcs_dag/run_id=scheduled__2023-05-25T00:00:00+00:00/task_id=bigquery_to_external_table_task_2015 permission to 509
[2023-05-26T08:27:41.285+0000] {taskinstance.py:1103} INFO - Dependencies all met for dep_context=non-requeueable deps ti=<TaskInstance: ingest_data_gcs_dag.bigquery_to_external_table_task_2015 scheduled__2023-05-25T00:00:00+00:00 [queued]>
[2023-05-26T08:27:41.306+0000] {taskinstance.py:1103} INFO - Dependencies all met for dep_context=requeueable deps ti=<TaskInstance: ingest_data_gcs_dag.bigquery_to_external_table_task_2015 scheduled__2023-05-25T00:00:00+00:00 [queued]>
[2023-05-26T08:27:41.308+0000] {taskinstance.py:1308} INFO - Starting attempt 2 of 2
[2023-05-26T08:27:41.339+0000] {taskinstance.py:1327} INFO - Executing <Task(BigQueryCreateExternalTableOperator): bigquery_to_external_table_task_2015> on 2023-05-25 00:00:00+00:00
[2023-05-26T08:27:41.349+0000] {standard_task_runner.py:57} INFO - Started process 323 to run task
[2023-05-26T08:27:41.358+0000] {standard_task_runner.py:84} INFO - Running: ['***', 'tasks', 'run', 'ingest_data_gcs_dag', 'bigquery_to_external_table_task_2015', 'scheduled__2023-05-25T00:00:00+00:00', '--job-id', '59', '--raw', '--subdir', 'DAGS_FOLDER/ingest_data_gcs_dag.py', '--cfg-path', '/tmp/tmpow2l9feg']
[2023-05-26T08:27:41.365+0000] {standard_task_runner.py:85} INFO - Job 59: Subtask bigquery_to_external_table_task_2015
[2023-05-26T08:27:41.450+0000] {logging_mixin.py:149} INFO - Changing /opt/***/logs/dag_id=ingest_data_gcs_dag/run_id=scheduled__2023-05-25T00:00:00+00:00/task_id=bigquery_to_external_table_task_2015 permission to 509
[2023-05-26T08:27:41.468+0000] {task_command.py:410} INFO - Running <TaskInstance: ingest_data_gcs_dag.bigquery_to_external_table_task_2015 scheduled__2023-05-25T00:00:00+00:00 [running]> on host 0d5f6a8dd67a
[2023-05-26T08:27:41.626+0000] {taskinstance.py:1547} INFO - Exporting env vars: AIRFLOW_CTX_DAG_OWNER='***' AIRFLOW_CTX_DAG_ID='ingest_data_gcs_dag' AIRFLOW_CTX_TASK_ID='bigquery_to_external_table_task_2015' AIRFLOW_CTX_EXECUTION_DATE='2023-05-25T00:00:00+00:00' AIRFLOW_CTX_TRY_NUMBER='2' AIRFLOW_CTX_DAG_RUN_ID='scheduled__2023-05-25T00:00:00+00:00'
[2023-05-26T08:27:41.631+0000] {crypto.py:83} WARNING - empty cryptography key - values will not be stored encrypted.
[2023-05-26T08:27:41.633+0000] {base.py:73} INFO - Using connection ID 'google_cloud_default' for task execution.
[2023-05-26T08:27:45.056+0000] {taskinstance.py:1824} ERROR - Task failed with exception
Traceback (most recent call last):
  File "/home/airflow/.local/lib/python3.7/site-packages/airflow/providers/google/cloud/operators/bigquery.py", line 1613, in execute
    table_resource=self.table_resource,
  File "/home/airflow/.local/lib/python3.7/site-packages/airflow/providers/google/common/hooks/base_google.py", line 468, in inner_wrapper
    return func(self, *args, **kwargs)
  File "/home/airflow/.local/lib/python3.7/site-packages/airflow/providers/google/cloud/hooks/bigquery.py", line 407, in create_empty_table
    table=table, exists_ok=exists_ok, retry=retry
  File "/home/airflow/.local/lib/python3.7/site-packages/google/cloud/bigquery/client.py", line 755, in create_table
    timeout=timeout,
  File "/home/airflow/.local/lib/python3.7/site-packages/google/cloud/bigquery/client.py", line 782, in _call_api
    return call()
  File "/home/airflow/.local/lib/python3.7/site-packages/google/api_core/retry.py", line 288, in retry_wrapped_func
    on_error=on_error,
  File "/home/airflow/.local/lib/python3.7/site-packages/google/api_core/retry.py", line 190, in retry_target
    return target()
  File "/home/airflow/.local/lib/python3.7/site-packages/google/cloud/_http/__init__.py", line 494, in api_request
    raise exceptions.from_http_response(response)
google.api_core.exceptions.Forbidden: 403 POST https://bigquery.googleapis.com/bigquery/v2/projects/bold-apricot-387206/datasets/horticulture_dataset/tables?prettyPrint=false: Access Denied: Dataset bold-apricot-387206:horticulture_dataset: Permission bigquery.tables.create denied on dataset bold-apricot-387206:horticulture_dataset (or it may not exist).
[2023-05-26T08:27:45.101+0000] {taskinstance.py:1350} INFO - Marking task as FAILED. dag_id=ingest_data_gcs_dag, task_id=bigquery_to_external_table_task_2015, execution_date=20230525T000000, start_date=20230526T082741, end_date=20230526T082745
[2023-05-26T08:27:45.153+0000] {standard_task_runner.py:109} ERROR - Failed to execute job 59 for task bigquery_to_external_table_task_2015 (403 POST https://bigquery.googleapis.com/bigquery/v2/projects/bold-apricot-387206/datasets/horticulture_dataset/tables?prettyPrint=false: Access Denied: Dataset bold-apricot-387206:horticulture_dataset: Permission bigquery.tables.create denied on dataset bold-apricot-387206:horticulture_dataset (or it may not exist).; 323)
[2023-05-26T08:27:45.202+0000] {local_task_job_runner.py:225} INFO - Task exited with return code 1
[2023-05-26T08:27:45.234+0000] {taskinstance.py:2651} INFO - 0 downstream tasks scheduled from follow-on schedule check
[2023-05-26T12:08:02.662+0000] {logging_mixin.py:149} INFO - Changing /opt/***/logs/dag_id=ingest_data_gcs_dag/run_id=scheduled__2023-05-25T00:00:00+00:00/task_id=bigquery_to_external_table_task_2015 permission to 509
[2023-05-26T12:08:02.719+0000] {logging_mixin.py:149} INFO - Changing /opt/***/logs/dag_id=ingest_data_gcs_dag/run_id=scheduled__2023-05-25T00:00:00+00:00/task_id=bigquery_to_external_table_task_2015 permission to 509
[2023-05-26T12:08:02.775+0000] {taskinstance.py:1103} INFO - Dependencies all met for dep_context=non-requeueable deps ti=<TaskInstance: ingest_data_gcs_dag.bigquery_to_external_table_task_2015 scheduled__2023-05-25T00:00:00+00:00 [queued]>
[2023-05-26T12:08:02.792+0000] {taskinstance.py:1103} INFO - Dependencies all met for dep_context=requeueable deps ti=<TaskInstance: ingest_data_gcs_dag.bigquery_to_external_table_task_2015 scheduled__2023-05-25T00:00:00+00:00 [queued]>
[2023-05-26T12:08:02.794+0000] {taskinstance.py:1308} INFO - Starting attempt 2 of 2
[2023-05-26T12:08:02.824+0000] {taskinstance.py:1327} INFO - Executing <Task(BigQueryCreateExternalTableOperator): bigquery_to_external_table_task_2015> on 2023-05-25 00:00:00+00:00
[2023-05-26T12:08:02.834+0000] {standard_task_runner.py:57} INFO - Started process 1357 to run task
[2023-05-26T12:08:02.842+0000] {standard_task_runner.py:84} INFO - Running: ['***', 'tasks', 'run', 'ingest_data_gcs_dag', 'bigquery_to_external_table_task_2015', 'scheduled__2023-05-25T00:00:00+00:00', '--job-id', '139', '--raw', '--subdir', 'DAGS_FOLDER/ingest_data_gcs_dag.py', '--cfg-path', '/tmp/tmpr38gpw0x']
[2023-05-26T12:08:02.846+0000] {standard_task_runner.py:85} INFO - Job 139: Subtask bigquery_to_external_table_task_2015
[2023-05-26T12:08:02.937+0000] {logging_mixin.py:149} INFO - Changing /opt/***/logs/dag_id=ingest_data_gcs_dag/run_id=scheduled__2023-05-25T00:00:00+00:00/task_id=bigquery_to_external_table_task_2015 permission to 509
[2023-05-26T12:08:02.954+0000] {task_command.py:410} INFO - Running <TaskInstance: ingest_data_gcs_dag.bigquery_to_external_table_task_2015 scheduled__2023-05-25T00:00:00+00:00 [running]> on host 335f5093005c
[2023-05-26T12:08:03.114+0000] {taskinstance.py:1547} INFO - Exporting env vars: AIRFLOW_CTX_DAG_OWNER='***' AIRFLOW_CTX_DAG_ID='ingest_data_gcs_dag' AIRFLOW_CTX_TASK_ID='bigquery_to_external_table_task_2015' AIRFLOW_CTX_EXECUTION_DATE='2023-05-25T00:00:00+00:00' AIRFLOW_CTX_TRY_NUMBER='2' AIRFLOW_CTX_DAG_RUN_ID='scheduled__2023-05-25T00:00:00+00:00'
[2023-05-26T12:08:03.120+0000] {crypto.py:83} WARNING - empty cryptography key - values will not be stored encrypted.
[2023-05-26T12:08:03.123+0000] {base.py:73} INFO - Using connection ID 'google_cloud_default' for task execution.
[2023-05-26T12:08:05.837+0000] {taskinstance.py:1824} ERROR - Task failed with exception
Traceback (most recent call last):
  File "/home/airflow/.local/lib/python3.7/site-packages/airflow/providers/google/cloud/operators/bigquery.py", line 1613, in execute
    table_resource=self.table_resource,
  File "/home/airflow/.local/lib/python3.7/site-packages/airflow/providers/google/common/hooks/base_google.py", line 468, in inner_wrapper
    return func(self, *args, **kwargs)
  File "/home/airflow/.local/lib/python3.7/site-packages/airflow/providers/google/cloud/hooks/bigquery.py", line 407, in create_empty_table
    table=table, exists_ok=exists_ok, retry=retry
  File "/home/airflow/.local/lib/python3.7/site-packages/google/cloud/bigquery/client.py", line 755, in create_table
    timeout=timeout,
  File "/home/airflow/.local/lib/python3.7/site-packages/google/cloud/bigquery/client.py", line 782, in _call_api
    return call()
  File "/home/airflow/.local/lib/python3.7/site-packages/google/api_core/retry.py", line 288, in retry_wrapped_func
    on_error=on_error,
  File "/home/airflow/.local/lib/python3.7/site-packages/google/api_core/retry.py", line 190, in retry_target
    return target()
  File "/home/airflow/.local/lib/python3.7/site-packages/google/cloud/_http/__init__.py", line 494, in api_request
    raise exceptions.from_http_response(response)
google.api_core.exceptions.Forbidden: 403 POST https://bigquery.googleapis.com/bigquery/v2/projects/bold-apricot-387206/datasets/horticulture_latest_dataset/tables?prettyPrint=false: Access Denied: Dataset bold-apricot-387206:horticulture_latest_dataset: Permission bigquery.tables.create denied on dataset bold-apricot-387206:horticulture_latest_dataset (or it may not exist).
[2023-05-26T12:08:05.878+0000] {taskinstance.py:1350} INFO - Marking task as FAILED. dag_id=ingest_data_gcs_dag, task_id=bigquery_to_external_table_task_2015, execution_date=20230525T000000, start_date=20230526T120802, end_date=20230526T120805
[2023-05-26T12:08:05.904+0000] {standard_task_runner.py:109} ERROR - Failed to execute job 139 for task bigquery_to_external_table_task_2015 (403 POST https://bigquery.googleapis.com/bigquery/v2/projects/bold-apricot-387206/datasets/horticulture_latest_dataset/tables?prettyPrint=false: Access Denied: Dataset bold-apricot-387206:horticulture_latest_dataset: Permission bigquery.tables.create denied on dataset bold-apricot-387206:horticulture_latest_dataset (or it may not exist).; 1357)
[2023-05-26T12:08:05.966+0000] {local_task_job_runner.py:225} INFO - Task exited with return code 1
[2023-05-26T12:08:06.018+0000] {taskinstance.py:2651} INFO - 0 downstream tasks scheduled from follow-on schedule check
