[2023-05-26T08:22:35.311+0000] {logging_mixin.py:149} INFO - Changing /opt/***/logs/dag_id=ingest_data_gcs_dag/run_id=scheduled__2023-05-25T00:00:00+00:00/task_id=bigquery_to_external_table_task_2015 permission to 509
[2023-05-26T08:22:35.381+0000] {logging_mixin.py:149} INFO - Changing /opt/***/logs/dag_id=ingest_data_gcs_dag/run_id=scheduled__2023-05-25T00:00:00+00:00/task_id=bigquery_to_external_table_task_2015 permission to 509
[2023-05-26T08:22:35.445+0000] {taskinstance.py:1103} INFO - Dependencies all met for dep_context=non-requeueable deps ti=<TaskInstance: ingest_data_gcs_dag.bigquery_to_external_table_task_2015 scheduled__2023-05-25T00:00:00+00:00 [queued]>
[2023-05-26T08:22:35.478+0000] {taskinstance.py:1103} INFO - Dependencies all met for dep_context=requeueable deps ti=<TaskInstance: ingest_data_gcs_dag.bigquery_to_external_table_task_2015 scheduled__2023-05-25T00:00:00+00:00 [queued]>
[2023-05-26T08:22:35.479+0000] {taskinstance.py:1308} INFO - Starting attempt 1 of 2
[2023-05-26T08:22:35.512+0000] {taskinstance.py:1327} INFO - Executing <Task(BigQueryCreateExternalTableOperator): bigquery_to_external_table_task_2015> on 2023-05-25 00:00:00+00:00
[2023-05-26T08:22:35.523+0000] {standard_task_runner.py:57} INFO - Started process 227 to run task
[2023-05-26T08:22:35.536+0000] {standard_task_runner.py:84} INFO - Running: ['***', 'tasks', 'run', 'ingest_data_gcs_dag', 'bigquery_to_external_table_task_2015', 'scheduled__2023-05-25T00:00:00+00:00', '--job-id', '57', '--raw', '--subdir', 'DAGS_FOLDER/ingest_data_gcs_dag.py', '--cfg-path', '/tmp/tmp7ps3_5e6']
[2023-05-26T08:22:35.541+0000] {standard_task_runner.py:85} INFO - Job 57: Subtask bigquery_to_external_table_task_2015
[2023-05-26T08:22:35.627+0000] {logging_mixin.py:149} INFO - Changing /opt/***/logs/dag_id=ingest_data_gcs_dag/run_id=scheduled__2023-05-25T00:00:00+00:00/task_id=bigquery_to_external_table_task_2015 permission to 509
[2023-05-26T08:22:35.643+0000] {task_command.py:410} INFO - Running <TaskInstance: ingest_data_gcs_dag.bigquery_to_external_table_task_2015 scheduled__2023-05-25T00:00:00+00:00 [running]> on host 0d5f6a8dd67a
[2023-05-26T08:22:35.783+0000] {taskinstance.py:1547} INFO - Exporting env vars: AIRFLOW_CTX_DAG_OWNER='***' AIRFLOW_CTX_DAG_ID='ingest_data_gcs_dag' AIRFLOW_CTX_TASK_ID='bigquery_to_external_table_task_2015' AIRFLOW_CTX_EXECUTION_DATE='2023-05-25T00:00:00+00:00' AIRFLOW_CTX_TRY_NUMBER='1' AIRFLOW_CTX_DAG_RUN_ID='scheduled__2023-05-25T00:00:00+00:00'
[2023-05-26T08:22:35.790+0000] {crypto.py:83} WARNING - empty cryptography key - values will not be stored encrypted.
[2023-05-26T08:22:35.792+0000] {base.py:73} INFO - Using connection ID 'google_cloud_default' for task execution.
[2023-05-26T08:22:39.056+0000] {taskinstance.py:1824} ERROR - Task failed with exception
Traceback (most recent call last):
  File "/home/airflow/.local/lib/python3.7/site-packages/airflow/providers/google/cloud/operators/bigquery.py", line 1613, in execute
    table_resource=self.table_resource,
  File "/home/airflow/.local/lib/python3.7/site-packages/airflow/providers/google/common/hooks/base_google.py", line 468, in inner_wrapper
    return func(self, *args, **kwargs)
  File "/home/airflow/.local/lib/python3.7/site-packages/airflow/providers/google/cloud/hooks/bigquery.py", line 407, in create_empty_table
    table=table, exists_ok=exists_ok, retry=retry
  File "/home/airflow/.local/lib/python3.7/site-packages/google/cloud/bigquery/client.py", line 755, in create_table
    timeout=timeout,
  File "/home/airflow/.local/lib/python3.7/site-packages/google/cloud/bigquery/client.py", line 782, in _call_api
    return call()
  File "/home/airflow/.local/lib/python3.7/site-packages/google/api_core/retry.py", line 288, in retry_wrapped_func
    on_error=on_error,
  File "/home/airflow/.local/lib/python3.7/site-packages/google/api_core/retry.py", line 190, in retry_target
    return target()
  File "/home/airflow/.local/lib/python3.7/site-packages/google/cloud/_http/__init__.py", line 494, in api_request
    raise exceptions.from_http_response(response)
google.api_core.exceptions.Forbidden: 403 POST https://bigquery.googleapis.com/bigquery/v2/projects/bold-apricot-387206/datasets/horticulture_dataset/tables?prettyPrint=false: Access Denied: Dataset bold-apricot-387206:horticulture_dataset: Permission bigquery.tables.create denied on dataset bold-apricot-387206:horticulture_dataset (or it may not exist).
[2023-05-26T08:22:39.097+0000] {taskinstance.py:1350} INFO - Marking task as UP_FOR_RETRY. dag_id=ingest_data_gcs_dag, task_id=bigquery_to_external_table_task_2015, execution_date=20230525T000000, start_date=20230526T082235, end_date=20230526T082239
[2023-05-26T08:22:39.125+0000] {standard_task_runner.py:109} ERROR - Failed to execute job 57 for task bigquery_to_external_table_task_2015 (403 POST https://bigquery.googleapis.com/bigquery/v2/projects/bold-apricot-387206/datasets/horticulture_dataset/tables?prettyPrint=false: Access Denied: Dataset bold-apricot-387206:horticulture_dataset: Permission bigquery.tables.create denied on dataset bold-apricot-387206:horticulture_dataset (or it may not exist).; 227)
[2023-05-26T08:22:39.181+0000] {local_task_job_runner.py:225} INFO - Task exited with return code 1
[2023-05-26T08:22:39.227+0000] {taskinstance.py:2651} INFO - 0 downstream tasks scheduled from follow-on schedule check
[2023-05-26T12:02:56.950+0000] {logging_mixin.py:149} INFO - Changing /opt/***/logs/dag_id=ingest_data_gcs_dag/run_id=scheduled__2023-05-25T00:00:00+00:00/task_id=bigquery_to_external_table_task_2015 permission to 509
[2023-05-26T12:02:57.027+0000] {logging_mixin.py:149} INFO - Changing /opt/***/logs/dag_id=ingest_data_gcs_dag/run_id=scheduled__2023-05-25T00:00:00+00:00/task_id=bigquery_to_external_table_task_2015 permission to 509
[2023-05-26T12:02:57.079+0000] {taskinstance.py:1103} INFO - Dependencies all met for dep_context=non-requeueable deps ti=<TaskInstance: ingest_data_gcs_dag.bigquery_to_external_table_task_2015 scheduled__2023-05-25T00:00:00+00:00 [queued]>
[2023-05-26T12:02:57.098+0000] {taskinstance.py:1103} INFO - Dependencies all met for dep_context=requeueable deps ti=<TaskInstance: ingest_data_gcs_dag.bigquery_to_external_table_task_2015 scheduled__2023-05-25T00:00:00+00:00 [queued]>
[2023-05-26T12:02:57.099+0000] {taskinstance.py:1308} INFO - Starting attempt 1 of 2
[2023-05-26T12:02:57.130+0000] {taskinstance.py:1327} INFO - Executing <Task(BigQueryCreateExternalTableOperator): bigquery_to_external_table_task_2015> on 2023-05-25 00:00:00+00:00
[2023-05-26T12:02:57.140+0000] {standard_task_runner.py:57} INFO - Started process 1250 to run task
[2023-05-26T12:02:57.148+0000] {standard_task_runner.py:84} INFO - Running: ['***', 'tasks', 'run', 'ingest_data_gcs_dag', 'bigquery_to_external_table_task_2015', 'scheduled__2023-05-25T00:00:00+00:00', '--job-id', '137', '--raw', '--subdir', 'DAGS_FOLDER/ingest_data_gcs_dag.py', '--cfg-path', '/tmp/tmpy_39yso2']
[2023-05-26T12:02:57.154+0000] {standard_task_runner.py:85} INFO - Job 137: Subtask bigquery_to_external_table_task_2015
[2023-05-26T12:02:57.241+0000] {logging_mixin.py:149} INFO - Changing /opt/***/logs/dag_id=ingest_data_gcs_dag/run_id=scheduled__2023-05-25T00:00:00+00:00/task_id=bigquery_to_external_table_task_2015 permission to 509
[2023-05-26T12:02:57.257+0000] {task_command.py:410} INFO - Running <TaskInstance: ingest_data_gcs_dag.bigquery_to_external_table_task_2015 scheduled__2023-05-25T00:00:00+00:00 [running]> on host 335f5093005c
[2023-05-26T12:02:57.410+0000] {taskinstance.py:1547} INFO - Exporting env vars: AIRFLOW_CTX_DAG_OWNER='***' AIRFLOW_CTX_DAG_ID='ingest_data_gcs_dag' AIRFLOW_CTX_TASK_ID='bigquery_to_external_table_task_2015' AIRFLOW_CTX_EXECUTION_DATE='2023-05-25T00:00:00+00:00' AIRFLOW_CTX_TRY_NUMBER='1' AIRFLOW_CTX_DAG_RUN_ID='scheduled__2023-05-25T00:00:00+00:00'
[2023-05-26T12:02:57.415+0000] {crypto.py:83} WARNING - empty cryptography key - values will not be stored encrypted.
[2023-05-26T12:02:57.417+0000] {base.py:73} INFO - Using connection ID 'google_cloud_default' for task execution.
[2023-05-26T12:03:01.027+0000] {taskinstance.py:1824} ERROR - Task failed with exception
Traceback (most recent call last):
  File "/home/airflow/.local/lib/python3.7/site-packages/airflow/providers/google/cloud/operators/bigquery.py", line 1613, in execute
    table_resource=self.table_resource,
  File "/home/airflow/.local/lib/python3.7/site-packages/airflow/providers/google/common/hooks/base_google.py", line 468, in inner_wrapper
    return func(self, *args, **kwargs)
  File "/home/airflow/.local/lib/python3.7/site-packages/airflow/providers/google/cloud/hooks/bigquery.py", line 407, in create_empty_table
    table=table, exists_ok=exists_ok, retry=retry
  File "/home/airflow/.local/lib/python3.7/site-packages/google/cloud/bigquery/client.py", line 755, in create_table
    timeout=timeout,
  File "/home/airflow/.local/lib/python3.7/site-packages/google/cloud/bigquery/client.py", line 782, in _call_api
    return call()
  File "/home/airflow/.local/lib/python3.7/site-packages/google/api_core/retry.py", line 288, in retry_wrapped_func
    on_error=on_error,
  File "/home/airflow/.local/lib/python3.7/site-packages/google/api_core/retry.py", line 190, in retry_target
    return target()
  File "/home/airflow/.local/lib/python3.7/site-packages/google/cloud/_http/__init__.py", line 494, in api_request
    raise exceptions.from_http_response(response)
google.api_core.exceptions.Forbidden: 403 POST https://bigquery.googleapis.com/bigquery/v2/projects/bold-apricot-387206/datasets/horticulture_latest_dataset/tables?prettyPrint=false: Access Denied: Dataset bold-apricot-387206:horticulture_latest_dataset: Permission bigquery.tables.create denied on dataset bold-apricot-387206:horticulture_latest_dataset (or it may not exist).
[2023-05-26T12:03:01.067+0000] {taskinstance.py:1350} INFO - Marking task as UP_FOR_RETRY. dag_id=ingest_data_gcs_dag, task_id=bigquery_to_external_table_task_2015, execution_date=20230525T000000, start_date=20230526T120257, end_date=20230526T120301
[2023-05-26T12:03:01.107+0000] {standard_task_runner.py:109} ERROR - Failed to execute job 137 for task bigquery_to_external_table_task_2015 (403 POST https://bigquery.googleapis.com/bigquery/v2/projects/bold-apricot-387206/datasets/horticulture_latest_dataset/tables?prettyPrint=false: Access Denied: Dataset bold-apricot-387206:horticulture_latest_dataset: Permission bigquery.tables.create denied on dataset bold-apricot-387206:horticulture_latest_dataset (or it may not exist).; 1250)
[2023-05-26T12:03:01.164+0000] {local_task_job_runner.py:225} INFO - Task exited with return code 1
[2023-05-26T12:03:01.196+0000] {taskinstance.py:2651} INFO - 0 downstream tasks scheduled from follow-on schedule check
