[2023-05-26T07:25:01.865+0000] {logging_mixin.py:149} INFO - Changing /opt/***/logs/dag_id=data_ingestion_gcs_dag/run_id=manual__2023-05-26T07:19:36.288103+00:00/task_id=bigquery_to_external_table_task_2016 permission to 509
[2023-05-26T07:25:01.948+0000] {logging_mixin.py:149} INFO - Changing /opt/***/logs/dag_id=data_ingestion_gcs_dag/run_id=manual__2023-05-26T07:19:36.288103+00:00/task_id=bigquery_to_external_table_task_2016 permission to 509
[2023-05-26T07:25:02.022+0000] {taskinstance.py:1103} INFO - Dependencies all met for dep_context=non-requeueable deps ti=<TaskInstance: data_ingestion_gcs_dag.bigquery_to_external_table_task_2016 manual__2023-05-26T07:19:36.288103+00:00 [queued]>
[2023-05-26T07:25:02.051+0000] {taskinstance.py:1103} INFO - Dependencies all met for dep_context=requeueable deps ti=<TaskInstance: data_ingestion_gcs_dag.bigquery_to_external_table_task_2016 manual__2023-05-26T07:19:36.288103+00:00 [queued]>
[2023-05-26T07:25:02.053+0000] {taskinstance.py:1308} INFO - Starting attempt 1 of 2
[2023-05-26T07:25:02.092+0000] {taskinstance.py:1327} INFO - Executing <Task(BigQueryCreateExternalTableOperator): bigquery_to_external_table_task_2016> on 2023-05-26 07:19:36.288103+00:00
[2023-05-26T07:25:02.108+0000] {standard_task_runner.py:57} INFO - Started process 380 to run task
[2023-05-26T07:25:02.123+0000] {standard_task_runner.py:84} INFO - Running: ['***', 'tasks', 'run', 'data_ingestion_gcs_dag', 'bigquery_to_external_table_task_2016', 'manual__2023-05-26T07:19:36.288103+00:00', '--job-id', '36', '--raw', '--subdir', 'DAGS_FOLDER/ingest_data_gcs_dag.py', '--cfg-path', '/tmp/tmpd1pat46w']
[2023-05-26T07:25:02.132+0000] {standard_task_runner.py:85} INFO - Job 36: Subtask bigquery_to_external_table_task_2016
[2023-05-26T07:25:02.258+0000] {logging_mixin.py:149} INFO - Changing /opt/***/logs/dag_id=data_ingestion_gcs_dag/run_id=manual__2023-05-26T07:19:36.288103+00:00/task_id=bigquery_to_external_table_task_2016 permission to 509
[2023-05-26T07:25:02.277+0000] {task_command.py:410} INFO - Running <TaskInstance: data_ingestion_gcs_dag.bigquery_to_external_table_task_2016 manual__2023-05-26T07:19:36.288103+00:00 [running]> on host 71de5723b7f9
[2023-05-26T07:25:02.506+0000] {taskinstance.py:1547} INFO - Exporting env vars: AIRFLOW_CTX_DAG_OWNER='***' AIRFLOW_CTX_DAG_ID='data_ingestion_gcs_dag' AIRFLOW_CTX_TASK_ID='bigquery_to_external_table_task_2016' AIRFLOW_CTX_EXECUTION_DATE='2023-05-26T07:19:36.288103+00:00' AIRFLOW_CTX_TRY_NUMBER='1' AIRFLOW_CTX_DAG_RUN_ID='manual__2023-05-26T07:19:36.288103+00:00'
[2023-05-26T07:25:02.514+0000] {crypto.py:83} WARNING - empty cryptography key - values will not be stored encrypted.
[2023-05-26T07:25:02.516+0000] {base.py:73} INFO - Using connection ID 'google_cloud_default' for task execution.
[2023-05-26T07:25:05.574+0000] {taskinstance.py:1824} ERROR - Task failed with exception
Traceback (most recent call last):
  File "/home/airflow/.local/lib/python3.7/site-packages/airflow/providers/google/cloud/operators/bigquery.py", line 1613, in execute
    table_resource=self.table_resource,
  File "/home/airflow/.local/lib/python3.7/site-packages/airflow/providers/google/common/hooks/base_google.py", line 468, in inner_wrapper
    return func(self, *args, **kwargs)
  File "/home/airflow/.local/lib/python3.7/site-packages/airflow/providers/google/cloud/hooks/bigquery.py", line 407, in create_empty_table
    table=table, exists_ok=exists_ok, retry=retry
  File "/home/airflow/.local/lib/python3.7/site-packages/google/cloud/bigquery/client.py", line 755, in create_table
    timeout=timeout,
  File "/home/airflow/.local/lib/python3.7/site-packages/google/cloud/bigquery/client.py", line 782, in _call_api
    return call()
  File "/home/airflow/.local/lib/python3.7/site-packages/google/api_core/retry.py", line 288, in retry_wrapped_func
    on_error=on_error,
  File "/home/airflow/.local/lib/python3.7/site-packages/google/api_core/retry.py", line 190, in retry_target
    return target()
  File "/home/airflow/.local/lib/python3.7/site-packages/google/cloud/_http/__init__.py", line 494, in api_request
    raise exceptions.from_http_response(response)
google.api_core.exceptions.Forbidden: 403 POST https://bigquery.googleapis.com/bigquery/v2/projects/bold-apricot-387206/datasets/horticulture_dataset/tables?prettyPrint=false: Access Denied: Dataset bold-apricot-387206:horticulture_dataset: Permission bigquery.tables.create denied on dataset bold-apricot-387206:horticulture_dataset (or it may not exist).
[2023-05-26T07:25:05.625+0000] {taskinstance.py:1350} INFO - Marking task as UP_FOR_RETRY. dag_id=data_ingestion_gcs_dag, task_id=bigquery_to_external_table_task_2016, execution_date=20230526T071936, start_date=20230526T072502, end_date=20230526T072505
[2023-05-26T07:25:05.665+0000] {standard_task_runner.py:109} ERROR - Failed to execute job 36 for task bigquery_to_external_table_task_2016 (403 POST https://bigquery.googleapis.com/bigquery/v2/projects/bold-apricot-387206/datasets/horticulture_dataset/tables?prettyPrint=false: Access Denied: Dataset bold-apricot-387206:horticulture_dataset: Permission bigquery.tables.create denied on dataset bold-apricot-387206:horticulture_dataset (or it may not exist).; 380)
[2023-05-26T07:25:05.722+0000] {local_task_job_runner.py:225} INFO - Task exited with return code 1
[2023-05-26T07:25:05.756+0000] {taskinstance.py:2651} INFO - 0 downstream tasks scheduled from follow-on schedule check
